Workbook

Sheet Pricing_model
A1: SKU | B1: Total_Cost | C1: Min_Price | D1: Target_Price | E1: Lowest_Competitor_Price | F1: Highest_Competitor_price | G1: Avg_Competitor_Price | H1: Days_of_Supply | I1: Weeks_of_Cover_t30 | J1: Avg_Acos14D | K1: Avg_Roas14D | L1: Conversion_Rate | M1: Base_Price | N1: After_Competitor_Price | O1: Inventory_Factory | P1: After_Inventory_Price | Q1: Demand_Factor | R1: After_Demand_Price | S1: Final_Recommended_Price | T1: Pricing_Reason | U1: Price_Increase_Potential | V1: Primary_Pricing_Driver
A2: MN-01 | B2: =IFERROR(INDEX(Pricing_Data[Total_Cost],MATCH(Pricing_model!A2,Pricing_Data[SKU],0)),"") -> 32.3 | C2: =INDEX(Pricing_Data[Min_Price],MATCH(A2,Pricing_Data[SKU],0)) -> 40.375 | D2: =INDEX(Pricing_Data[Target_Price],MATCH(Pricing_model!A2,Pricing_Data[SKU],0)) -> 49.692308 | E2: =INDEX(Competitor_Data[Lowest_Competitor_Price],MATCH(Pricing_model!A2,Competitor_Data[SKU],0)) -> 31.95 | F2: =INDEX(Competitor_Data[Highest_Competitor_Price],MATCH(Pricing_model!A2,Competitor_Data[SKU],0)) -> 44.9 | G2: =INDEX(Competitor_Data[Avg_Competitor_Price],MATCH(Pricing_model!A2,Competitor_Data[SKU],0)) -> 36.9 | H2: =INDEX(Inventory_Health__2[days-of-supply],MATCH(Pricing_model!A2,Inventory_Health__2[SKU],0)) -> 47 | I2: =INDEX(Inventory_Health__2[weeks-of-cover-t30],MATCH(Pricing_model!A2,Inventory_Health__2[SKU],0)) -> 6 | J2: =INDEX(Ads_Performance!AF12:AF61,MATCH(Pricing_model!A2,Ads_Performance!AE12:AE61,0)) -> 31.486923 | K2: =INDEX(Ads_Performance!AG12:AG61,MATCH(Pricing_model!A2,Ads_Performance!AE12:AE61,0)) -> 6.0015491 | L2: =INDEX(Historical_Sales!O8:O57,MATCH(Pricing_model!A2,Historical_Sales!L8:L57,0)) -> 0.30557002 | M2: =D2 -> 49.692308 | N2: =IF(AND(G2<>"", M2> G2),G2,M2) -> 36.9 | O2: =IF( H2=0, 1, IF( H2 < 45, 1.05, IF( H2 > 90, 0.95, IF( I2 > 10, 0.95, 1 ) ) ) ) -> 1 | P2: =N2*O2 -> 36.9 | Q2: =IF( AND(K2>=6, L2>=0.3, J2<=35), 1.03, IF(OR(J2>35, K2<3), 0.95, 1) ) -> 1.03 | R2: =P2*Q2 -> 38.007 | S2: =MAX(R2,C2) -> 40.375 | T2: =_xlfn.TEXTJOIN(", ", TRUE, IF(H2 < 15, "Low inventory", ""), IF(I2 > 8, "Overstock", ""), IF(G2<>"", "Competitor benchmark", ""), IF(K2 > 3, "Strong ads", ""), IF(J2 > 0.4, "High ad cost", "") ) -> Competitor benchmark, Strong ads, High ad cost | U2: =IF(Table3[[#This Row],[Final_Recommended_Price]]>Table3[[#This Row],[Min_Price]],"Yes","No") -> No | V2: =IF( S2=C2, "Minimum margin constraint", IF( G2<>"", "Competitor benchmark", IF( O2>1, "Low inventory", IF( O2<1, "Overstock", IF( Q2>1, "Strong demand / ads", IF(Q2<1, "High ad cost", "Neutral") ) ) ) ) ) -> Minimum margin constraint
A3: MN-02 | B3: =IFERROR(INDEX(Pricing_Data[Total_Cost],MATCH(Pricing_model!A3,Pricing_Data[SKU],0)),"") -> 26.6 | C3: =INDEX(Pricing_Data[Min_Price],MATCH(A3,Pricing_Data[SKU],0)) -> 33.25 | D3: =INDEX(Pricing_Data[Target_Price],MATCH(Pricing_model!A3,Pricing_Data[SKU],0)) -> 40.923077 | E3: =INDEX(Competitor_Data[Lowest_Competitor_Price],MATCH(Pricing_model!A3,Competitor_Data[SKU],0)) -> 27.9 | F3: =INDEX(Competitor_Data[Highest_Competitor_Price],MATCH(Pricing_model!A3,Competitor_Data[SKU],0)) -> 39.95 | G3: =INDEX(Competitor_Data[Avg_Competitor_Price],MATCH(Pricing_model!A3,Competitor_Data[SKU],0)) -> 32.5 | H3: =INDEX(Inventory_Health__2[days-of-supply],MATCH(Pricing_model!A3,Inventory_Health__2[SKU],0)) -> 85 | I3: =INDEX(Inventory_Health__2[weeks-of-cover-t30],MATCH(Pricing_model!A3,Inventory_Health__2[SKU],0)) -> 7 | J3: =INDEX(Ads_Performance!AF13:AF62,MATCH(Pricing_model!A3,Ads_Performance!AE13:AE62,0)) -> 17.429955 | K3: =INDEX(Ads_Performance!AG13:AG62,MATCH(Pricing_model!A3,Ads_Performance!AE13:AE62,0)) -> 11.141498 | L3: =INDEX(Historical_Sales!O9:O58,MATCH(Pricing_model!A3,Historical_Sales!L9:L58,0)) -> 0.2339848 | M3: =D3 -> 40.923077 | N3: =IF(AND(G3<>"", M3> G3),G3,M3) -> 32.5 | O3: =IF( H3=0, 1, IF( H3 < 45, 1.05, IF( H3 > 90, 0.95, IF( I3 > 10, 0.95, 1 ) ) ) ) -> 1 | P3: =N3*O3 -> 32.5 | Q3: =IF( AND(K3>=6, L3>=0.3, J3<=35), 1.03, IF(OR(J3>35, K3<3), 0.95, 1) ) -> 1 | R3: =P3*Q3 -> 32.5 | S3: =MAX(R3,C3) -> 33.25 | T3: =_xlfn.TEXTJOIN(", ", TRUE, IF(H3 < 15, "Low inventory", ""), IF(I3 > 8, "Overstock", ""), IF(G3<>"", "Competitor benchmark", ""), IF(K3 > 3, "Strong ads", ""), IF(J3 > 0.4, "High ad cost", "") ) -> Competitor benchmark, Strong ads, High ad cost | U3: =IF(Table3[[#This Row],[Final_Recommended_Price]]>Table3[[#This Row],[Min_Price]],"Yes","No") -> No | V3: =IF( S3=C3, "Minimum margin constraint", IF( G3<>"", "Competitor benchmark", IF( O3>1, "Low inventory", IF( O3<1, "Overstock", IF( Q3>1, "Strong demand / ads", IF(Q3<1, "High ad cost", "Neutral") ) ) ) ) ) -> Minimum margin constraint
A4: MN-03 | B4: =IFERROR(INDEX(Pricing_Data[Total_Cost],MATCH(Pricing_model!A4,Pricing_Data[SKU],0)),"") -> 30.03 | C4: =INDEX(Pricing_Data[Min_Price],MATCH(A4,Pricing_Data[SKU],0)) -> 37.5375 | D4: =INDEX(Pricing_Data[Target_Price],MATCH(Pricing_model!A4,Pricing_Data[SKU],0)) -> 46.2 | E4: =INDEX(Competitor_Data[Lowest_Competitor_Price],MATCH(Pricing_model!A4,Competitor_Data[SKU],0)) -> 29.99 | F4: =INDEX(Competitor_Data[Highest_Competitor_Price],MATCH(Pricing_model!A4,Competitor_Data[SKU],0)) -> 42.5 | G4: =INDEX(Competitor_Data[Avg_Competitor_Price],MATCH(Pricing_model!A4,Competitor_Data[SKU],0)) -> 35.2 | H4: =INDEX(Inventory_Health__2[days-of-supply],MATCH(Pricing_model!A4,Inventory_Health__2[SKU],0)) -> 83 | I4: =INDEX(Inventory_Health__2[weeks-of-cover-t30],MATCH(Pricing_model!A4,Inventory_Health__2[SKU],0)) -> 8 | J4: =INDEX(Ads_Performance!AF14:AF63,MATCH(Pricing_model!A4,Ads_Performance!AE14:AE63,0)) -> 14.183546 | K4: =INDEX(Ads_Performance!AG14:AG63,MATCH(Pricing_model!A4,Ads_Performance!AE14:AE63,0)) -> 10.859895 | L4: =INDEX(Historical_Sales!O10:O59,MATCH(Pricing_model!A4,Historical_Sales!L10:L59,0)) -> 0.22817229 | M4: =D4 -> 46.2 | N4: =IF(AND(G4<>"", M4> G4),G4,M4) -> 35.2 | O4: =IF( H4=0, 1, IF( H4 < 45, 1.05, IF( H4 > 90, 0.95, IF( I4 > 10, 0.95, 1 ) ) ) ) -> 1 | P4: =N4*O4 -> 35.2 | Q4: =IF( AND(K4>=6, L4>=0.3, J4<=35), 1.03, IF(OR(J4>35, K4<3), 0.95, 1) ) -> 1 | R4: =P4*Q4 -> 35.2 | S4: =MAX(R4,C4) -> 37.5375 | T4: =_xlfn.TEXTJOIN(", ", TRUE, IF(H4 < 15, "Low inventory", ""), IF(I4 > 8, "Overstock", ""), IF(G4<>"", "Competitor benchmark", ""), IF(K4 > 3, "Strong ads", ""), IF(J4 > 0.4, "High ad cost", "") ) -> Competitor benchmark, Strong ads, High ad cost | U4: =IF(Table3[[#This Row],[Final_Recommended_Price]]>Table3[[#This Row],[Min_Price]],"Yes","No") -> No | V4: =IF( S4=C4, "Minimum margin constraint", IF( G4<>"", "Competitor benchmark", IF( O4>1, "Low inventory", IF( O4<1, "Overstock", IF( Q4>1, "Strong demand / ads", IF(Q4<1, "High ad cost", "Neutral") ) ) ) ) ) -> Minimum margin constraint
A5: MN-04 | B5: =IFERROR(INDEX(Pricing_Data[Total_Cost],MATCH(Pricing_model!A5,Pricing_Data[SKU],0)),"") -> 25.94 | C5: =INDEX(Pricing_Data[Min_Price],MATCH(A5,Pricing_Data[SKU],0)) -> 32.425 | D5: =INDEX(Pricing_Data[Target_Price],MATCH(Pricing_model!A5,Pricing_Data[SKU],0)) -> 39.907692 | E5: =INDEX(Competitor_Data[Lowest_Competitor_Price],MATCH(Pricing_model!A5,Competitor_Data[SKU],0)) -> 24.5 | F5: =INDEX(Competitor_Data[Highest_Competitor_Price],MATCH(Pricing_model!A5,Competitor_Data[SKU],0)) -> 35.9 | G5: =INDEX(Competitor_Data[Avg_Competitor_Price],MATCH(Pricing_model!A5,Competitor_Data[SKU],0)) -> 28.4 | H5: =INDEX(Inventory_Health__2[days-of-supply],MATCH(Pricing_model!A5,Inventory_Health__2[SKU],0)) -> 99 | I5: =INDEX(Inventory_Health__2[weeks-of-cover-t30],MATCH(Pricing_model!A5,Inventory_Health__2[SKU],0)) -> 8 | J5: =INDEX(Ads_Performance!AF15:AF64,MATCH(Pricing_model!A5,Ads_Performance!AE15:AE64,0)) -> 40.747658 | K5: =INDEX(Ads_Performance!AG15:AG64,MATCH(Pricing_model!A5,Ads_Performance!AE15:AE64,0)) -> 5.490357 | L5: =INDEX(Historical_Sales!O11:O60,MATCH(Pricing_model!A5,Historical_Sales!L11:L60,0)) -> 0.31622517 | M5: =D5 -> 39.907692 | N5: =IF(AND(G5<>"", M5> G5),G5,M5) -> 28.4 | O5: =IF( H5=0, 1, IF( H5 < 45, 1.05, IF( H5 > 90, 0.95, IF( I5 > 10, 0.95, 1 ) ) ) ) -> 0.95 | P5: =N5*O5 -> 26.98 | Q5: =IF( AND(K5>=6, L5>=0.3, J5<=35), 1.03, IF(OR(J5>35, K5<3), 0.95, 1) ) -> 0.95 | R5: =P5*Q5 -> 25.631 | S5: =MAX(R5,C5) -> 32.425 | T5: =_xlfn.TEXTJOIN(", ", TRUE, IF(H5 < 15, "Low inventory", ""), IF(I5 > 8, "Overstock", ""), IF(G5<>"", "Competitor benchmark", ""), IF(K5 > 3, "Strong ads", ""), IF(J5 > 0.4, "High ad cost", "") ) -> Competitor benchmark, Strong ads, High ad cost | U5: =IF(Table3[[#This Row],[Final_Recommended_Price]]>Table3[[#This Row],[Min_Price]],"Yes","No") -> No | V5: =IF( S5=C5, "Minimum margin constraint", IF( G5<>"", "Competitor benchmark", IF( O5>1, "Low inventory", IF( O5<1, "Overstock", IF( Q5>1, "Strong demand / ads", IF(Q5<1, "High ad cost", "Neutral") ) ) ) ) ) -> Minimum margin constraint
A6: MN-05 | B6: =IFERROR(INDEX(Pricing_Data[Total_Cost],MATCH(Pricing_model!A6,Pricing_Data[SKU],0)),"") -> 25.77 | C6: =INDEX(Pricing_Data[Min_Price],MATCH(A6,Pricing_Data[SKU],0)) -> 34.36 | D6: =INDEX(Pricing_Data[Target_Price],MATCH(Pricing_model!A6,Pricing_Data[SKU],0)) -> 46.854545 | E6: =INDEX(Competitor_Data[Lowest_Competitor_Price],MATCH(Pricing_model!A6,Competitor_Data[SKU],0)) -> 18.95 | F6: =INDEX(Competitor_Data[Highest_Competitor_Price],MATCH(Pricing_model!A6,Competitor_Data[SKU],0)) -> 0 | G6: =INDEX(Competitor_Data[Avg_Competitor_Price],MATCH(Pricing_model!A6,Competitor_Data[SKU],0)) -> 23.9 | H6: =INDEX(Inventory_Health__2[days-of-supply],MATCH(Pricing_model!A6,Inventory_Health__2[SKU],0)) -> 145 | I6: =INDEX(Inventory_Health__2[weeks-of-cover-t30],MATCH(Pricing_model!A6,Inventory_Health__2[SKU],0)) -> 0 | J6: =INDEX(Ads_Performance!AF16:AF65,MATCH(Pricing_model!A6,Ads_Performance!AE16:AE65,0)) -> 25.843374 | K6: =INDEX(Ads_Performance!AG16:AG65,MATCH(Pricing_model!A6,Ads_Performance!AE16:AE65,0)) -> 2.5731512 | L6: =INDEX(Historical_Sales!O12:O61,MATCH(Pricing_model!A6,Historical_Sales!L12:L61,0)) -> 0.17788211 | M6: =D6 -> 46.854545 | N6: =IF(AND(G6<>"", M6> G6),G6,M6) -> 23.9 | O6: =IF( H6=0, 1, IF( H6 < 45, 1.05, IF( H6 > 90, 0.95, IF( I6 > 10, 0.95, 1 ) ) ) ) -> 0.95 | P6: =N6*O6 -> 22.705 | Q6: =IF( AND(K6>=6, L6>=0.3, J6<=35), 1.03, IF(OR(J6>35, K6<3), 0.95, 1) ) -> 0.95 | R6: =P6*Q6 -> 21.56975 | S6: =MAX(R6,C6) -> 34.36 | T6: =_xlfn.TEXTJOIN(", ", TRUE, IF(H6 < 15, "Low inventory", ""), IF(I6 > 8, "Overstock", ""), IF(G6<>"", "Competitor benchmark", ""), IF(K6 > 3, "Strong ads", ""), IF(J6 > 0.4, "High ad cost", "") ) -> Competitor benchmark, High ad cost | U6: =IF(Table3[[#This Row],[Final_Recommended_Price]]>Table3[[#This Row],[Min_Price]],"Yes","No") -> No | V6: =IF( S6=C6, "Minimum margin constraint", IF( G6<>"", "Competitor benchmark", IF( O6>1, "Low inventory", IF( O6<1, "Overstock", IF( Q6>1, "Strong demand / ads", IF(Q6<1, "High ad cost", "Neutral") ) ) ) ) ) -> Minimum margin constraint
A7: MN-06 | B7: =IFERROR(INDEX(Pricing_Data[Total_Cost],MATCH(Pricing_model!A7,Pricing_Data[SKU],0)),"") -> 14.37 | C7: =INDEX(Pricing_Data[Min_Price],MATCH(A7,Pricing_Data[SKU],0)) -> 19.16 | D7: =INDEX(Pricing_Data[Target_Price],MATCH(Pricing_model!A7,Pricing_Data[SKU],0)) -> 26.127273 | E7: =INDEX(Competitor_Data[Lowest_Competitor_Price],MATCH(Pricing_model!A7,Competitor_Data[SKU],0)) -> 12.99 | F7: =INDEX(Competitor_Data[Highest_Competitor_Price],MATCH(Pricing_model!A7,Competitor_Data[SKU],0)) -> 21.5 | G7: =INDEX(Competitor_Data[Avg_Competitor_Price],MATCH(Pricing_model!A7,Competitor_Data[SKU],0)) -> 15.8 | H7: =INDEX(Inventory_Health__2[days-of-supply],MATCH(Pricing_model!A7,Inventory_Health__2[SKU],0)) -> 0 | I7: =INDEX(Inventory_Health__2[weeks-of-cover-t30],MATCH(Pricing_model!A7,Inventory_Health__2[SKU],0)) -> 0 | J7: =INDEX(Ads_Performance!AF17:AF66,MATCH(Pricing_model!A7,Ads_Performance!AE17:AE66,0)) -> 49.906491 | K7: =INDEX(Ads_Performance!AG17:AG66,MATCH(Pricing_model!A7,Ads_Performance!AE17:AE66,0)) -> 1.8697301 | L7: =INDEX(Historical_Sales!O13:O62,MATCH(Pricing_model!A7,Historical_Sales!L13:L62,0)) -> 0.22064057 | M7: =D7 -> 26.127273 | N7: =IF(AND(G7<>"", M7> G7),G7,M7) -> 15.8 | O7: =IF( H7=0, 1, IF( H7 < 45, 1.05, IF( H7 > 90, 0.95, IF( I7 > 10, 0.95, 1 ) ) ) ) -> 1 | P7: =N7*O7 -> 15.8 | Q7: =IF( AND(K7>=6, L7>=0.3, J7<=35), 1.03, IF(OR(J7>35, K7<3), 0.95, 1) ) -> 0.95 | R7: =P7*Q7 -> 15.01 | S7: =MAX(R7,C7) -> 19.16 | T7: =_xlfn.TEXTJOIN(", ", TRUE, IF(H7 < 15, "Low inventory", ""), IF(I7 > 8, "Overstock", ""), IF(G7<>"", "Competitor benchmark", ""), IF(K7 > 3, "Strong ads", ""), IF(J7 > 0.4, "High ad cost", "") ) -> Low inventory, Competitor benchmark, High ad cost | U7: =IF(Table3[[#This Row],[Final_Recommended_Price]]>Table3[[#This Row],[Min_Price]],"Yes","No") -> No | V7: =IF( S7=C7, "Minimum margin constraint", IF( G7<>"", "Competitor benchmark", IF( O7>1, "Low inventory", IF( O7<1, "Overstock", IF( Q7>1, "Strong demand / ads", IF(Q7<1, "High ad cost", "Neutral") ) ) ) ) ) -> Minimum margin constraint
A8: MN-07 | B8: =IFERROR(INDEX(Pricing_Data[Total_Cost],MATCH(Pricing_model!A8,Pricing_Data[SKU],0)),"") -> 71.46 | C8: =INDEX(Pricing_Data[Min_Price],MATCH(A8,Pricing_Data[SKU],0)) -> 89.325 | D8: =INDEX(Pricing_Data[Target_Price],MATCH(Pricing_model!A8,Pricing_Data[SKU],0)) -> 109.93846 | E8: =INDEX(Competitor_Data[Lowest_Competitor_Price],MATCH(Pricing_model!A8,Competitor_Data[SKU],0)) -> 28.9 | F8: =INDEX(Competitor_Data[Highest_Competitor_Price],MATCH(Pricing_model!A8,Competitor_Data[SKU],0)) -> 41.95 | G8: =INDEX(Competitor_Data[Avg_Competitor_Price],MATCH(Pricing_model!A8,Competitor_Data[SKU],0)) -> 33.5 | H8: =INDEX(Inventory_Health__2[days-of-supply],MATCH(Pricing_model!A8,Inventory_Health__2[SKU],0)) -> 59 | I8: =INDEX(Inventory_Health__2[weeks-of-cover-t30],MATCH(Pricing_model!A8,Inventory_Health__2[SKU],0)) -> 5 | J8: =INDEX(Ads_Performance!AF18:AF67,MATCH(Pricing_model!A8,Ads_Performance!AE18:AE67,0)) -> 10.698216 | K8: =INDEX(Ads_Performance!AG18:AG67,MATCH(Pricing_model!A8,Ads_Performance!AE18:AE67,0)) -> 8.6299209 | L8: =INDEX(Historical_Sales!O14:O63,MATCH(Pricing_model!A8,Historical_Sales!L14:L63,0)) -> 0.13002755 | M8: =D8 -> 109.93846 | N8: =IF(AND(G8<>"", M8> G8),G8,M8) -> 33.5 | O8: =IF( H8=0, 1, IF( H8 < 45, 1.05, IF( H8 > 90, 0.95, IF( I8 > 10, 0.95, 1 ) ) ) ) -> 1 | P8: =N8*O8 -> 33.5 | Q8: =IF( AND(K8>=6, L8>=0.3, J8<=35), 1.03, IF(OR(J8>35, K8<3), 0.95, 1) ) -> 1 | R8: =P8*Q8 -> 33.5 | S8: =MAX(R8,C8) -> 89.325 | T8: =_xlfn.TEXTJOIN(", ", TRUE, IF(H8 < 15, "Low inventory", ""), IF(I8 > 8, "Overstock", ""), IF(G8<>"", "Competitor benchmark", ""), IF(K8 > 3, "Strong ads", ""), IF(J8 > 0.4, "High ad cost", "") ) -> Competitor benchmark, Strong ads, High ad cost | U8: =IF(Table3[[#This Row],[Final_Recommended_Price]]>Table3[[#This Row],[Min_Price]],"Yes","No") -> No | V8: =IF( S8=C8, "Minimum margin constraint", IF( G8<>"", "Competitor benchmark", IF( O8>1, "Low inventory", IF( O8<1, "Overstock", IF( Q8>1, "Strong demand / ads", IF(Q8<1, "High ad cost", "Neutral") ) ) ) ) ) -> Minimum margin constraint
A9: MN-08 | B9: =IFERROR(INDEX(Pricing_Data[Total_Cost],MATCH(Pricing_model!A9,Pricing_Data[SKU],0)),"") -> 26.11 | C9: =INDEX(Pricing_Data[Min_Price],MATCH(A9,Pricing_Data[SKU],0)) -> 34.813333 | D9: =INDEX(Pricing_Data[Target_Price],MATCH(Pricing_model!A9,Pricing_Data[SKU],0)) -> 47.472727 | E9: =INDEX(Competitor_Data[Lowest_Competitor_Price],MATCH(Pricing_model!A9,Competitor_Data[SKU],0)) -> 25.95 | F9: =INDEX(Competitor_Data[Highest_Competitor_Price],MATCH(Pricing_model!A9,Competitor_Data[SKU],0)) -> 39.9 | G9: =INDEX(Competitor_Data[Avg_Competitor_Price],MATCH(Pricing_model!A9,Competitor_Data[SKU],0)) -> 31.2 | H9: =INDEX(Inventory_Health__2[days-of-supply],MATCH(Pricing_model!A9,Inventory_Health__2[SKU],0)) -> 103 | I9: =INDEX(Inventory_Health__2[weeks-of-cover-t30],MATCH(Pricing_model!A9,Inventory_Health__2[SKU],0)) -> 98 | J9: =INDEX(Ads_Performance!AF19:AF68,MATCH(Pricing_model!A9,Ads_Performance!AE19:AE68,0)) -> 4.6143725 | K9: =INDEX(Ads_Performance!AG19:AG68,MATCH(Pricing_model!A9,Ads_Performance!AE19:AE68,0)) -> 9.9317801 | L9: =INDEX(Historical_Sales!O15:O64,MATCH(Pricing_model!A9,Historical_Sales!L15:L64,0)) -> 0.25595238 | M9: =D9 -> 47.472727 | N9: =IF(AND(G9<>"", M9> G9),G9,M9) -> 31.2 | O9: =IF( H9=0, 1, IF( H9 < 45, 1.05, IF( H9 > 90, 0.95, IF( I9 > 10, 0.95, 1 ) ) ) ) -> 0.95 | P9: =N9*O9 -> 29.64 | Q9: =IF( AND(K9>=6, L9>=0.3, J9<=35), 1.03, IF(OR(J9>35, K9<3), 0.95, 1) ) -> 1 | R9: =P9*Q9 -> 29.64 | S9: =MAX(R9,C9) -> 34.813333 | T9: =_xlfn.TEXTJOIN(", ", TRUE, IF(H9 < 15, "Low inventory", ""), IF(I9 > 8, "Overstock", ""), IF(G9<>"", "Competitor benchmark", ""), IF(K9 > 3, "Strong ads", ""), IF(J9 > 0.4, "High ad cost", "") ) -> Overstock, Competitor benchmark, Strong ads, High ad cost | U9: =IF(Table3[[#This Row],[Final_Recommended_Price]]>Table3[[#This Row],[Min_Price]],"Yes","No") -> No | V9: =IF( S9=C9, "Minimum margin constraint", IF( G9<>"", "Competitor benchmark", IF( O9>1, "Low inventory", IF( O9<1, "Overstock", IF( Q9>1, "Strong demand / ads", IF(Q9<1, "High ad cost", "Neutral") ) ) ) ) ) -> Minimum margin constraint
A10: MN-09 | B10: =IFERROR(INDEX(Pricing_Data[Total_Cost],MATCH(Pricing_model!A10,Pricing_Data[SKU],0)),"") -> 14.92 | C10: =INDEX(Pricing_Data[Min_Price],MATCH(A10,Pricing_Data[SKU],0)) -> 19.893333 | D10: =INDEX(Pricing_Data[Target_Price],MATCH(Pricing_model!A10,Pricing_Data[SKU],0)) -> 27.127273 | E10: =INDEX(Competitor_Data[Lowest_Competitor_Price],MATCH(Pricing_model!A10,Competitor_Data[SKU],0)) -> 11.99 | F10: =INDEX(Competitor_Data[Highest_Competitor_Price],MATCH(Pricing_model!A10,Competitor_Data[SKU],0)) -> 22.9 | G10: =INDEX(Competitor_Data[Avg_Competitor_Price],MATCH(Pricing_model!A10,Competitor_Data[SKU],0)) -> 15.6 | H10: =INDEX(Inventory_Health__2[days-of-supply],MATCH(Pricing_model!A10,Inventory_Health__2[SKU],0)) -> 57 | I10: =INDEX(Inventory_Health__2[weeks-of-cover-t30],MATCH(Pricing_model!A10,Inventory_Health__2[SKU],0)) -> 43 | J10: =INDEX(Ads_Performance!AF20:AF69,MATCH(Pricing_model!A10,Ads_Performance!AE20:AE69,0)) -> 13.280875 | K10: =INDEX(Ads_Performance!AG20:AG69,MATCH(Pricing_model!A10,Ads_Performance!AE20:AE69,0)) -> 3.982438 | L10: =INDEX(Historical_Sales!O16:O65,MATCH(Pricing_model!A10,Historical_Sales!L16:L65,0)) -> 0.15728155 | M10: =D10 -> 27.127273 | N10: =IF(AND(G10<>"", M10> G10),G10,M10) -> 15.6 | O10: =IF( H10=0, 1, IF( H10 < 45, 1.05, IF( H10 > 90, 0.95, IF( I10 > 10, 0.95, 1 ) ) ) ) -> 0.95 | P10: =N10*O10 -> 14.82 | Q10: =IF( AND(K10>=6, L10>=0.3, J10<=35), 1.03, IF(OR(J10>35, K10<3), 0.95, 1) ) -> 1 | R10: =P10*Q10 -> 14.82 | S10: =MAX(R10,C10) -> 19.893333 | T10: =_xlfn.TEXTJOIN(", ", TRUE, IF(H10 < 15, "Low inventory", ""), IF(I10 > 8, "Overstock", ""), IF(G10<>"", "Competitor benchmark", ""), IF(K10 > 3, "Strong ads", ""), IF(J10 > 0.4, "High ad cost", "") ) -> Overstock, Competitor benchmark, Strong ads, High ad cost | U10: =IF(Table3[[#This Row],[Final_Recommended_Price]]>Table3[[#This Row],[Min_Price]],"Yes","No") -> No | V10: =IF( S10=C10, "Minimum margin constraint", IF( G10<>"", "Competitor benchmark", IF( O10>1, "Low inventory", IF( O10<1, "Overstock", IF( Q10>1, "Strong demand / ads", IF(Q10<1, "High ad cost", "Neutral") ) ) ) ) ) -> Minimum margin constraint
A11: MN-10 | B11: =IFERROR(INDEX(Pricing_Data[Total_Cost],MATCH(Pricing_model!A11,Pricing_Data[SKU],0)),"") -> 17.4 | C11: =INDEX(Pricing_Data[Min_Price],MATCH(A11,Pricing_Data[SKU],0)) -> 21.75 | D11: =INDEX(Pricing_Data[Target_Price],MATCH(Pricing_model!A11,Pricing_Data[SKU],0)) -> 26.769231 | E11: =INDEX(Competitor_Data[Lowest_Competitor_Price],MATCH(Pricing_model!A11,Competitor_Data[SKU],0)) -> 16.95 | F11: =INDEX(Competitor_Data[Highest_Competitor_Price],MATCH(Pricing_model!A11,Competitor_Data[SKU],0)) -> 26.9 | G11: =INDEX(Competitor_Data[Avg_Competitor_Price],MATCH(Pricing_model!A11,Competitor_Data[SKU],0)) -> 20.5 | H11: =INDEX(Inventory_Health__2[days-of-supply],MATCH(Pricing_model!A11,Inventory_Health__2[SKU],0)) -> 150 | I11: =INDEX(Inventory_Health__2[weeks-of-cover-t30],MATCH(Pricing_model!A11,Inventory_Health__2[SKU],0)) -> 10 | J11: =INDEX(Ads_Performance!AF21:AF70,MATCH(Pricing_model!A11,Ads_Performance!AE21:AE70,0)) -> 18.167006 | K11: =INDEX(Ads_Performance!AG21:AG70,MATCH(Pricing_model!A11,Ads_Performance!AE21:AE70,0)) -> 5.7078558 | L11: =INDEX(Historical_Sales!O17:O66,MATCH(Pricing_model!A11,Historical_Sales!L17:L66,0)) -> 0.17801858 | M11: =D11 -> 26.769231 | N11: =IF(AND(G11<>"", M11> G11),G11,M11) -> 20.5 | O11: =IF( H11=0, 1, IF( H11 < 45, 1.05, IF( H11 > 90, 0.95, IF( I11 > 10, 0.95, 1 ) ) ) ) -> 0.95 | P11: =N11*O11 -> 19.475 | Q11: =IF( AND(K11>=6, L11>=0.3, J11<=35), 1.03, IF(OR(J11>35, K11<3), 0.95, 1) ) -> 1 | R11: =P11*Q11 -> 19.475 | S11: =MAX(R11,C11) -> 21.75 | T11: =_xlfn.TEXTJOIN(", ", TRUE, IF(H11 < 15, "Low inventory", ""), IF(I11 > 8, "Overstock", ""), IF(G11<>"", "Competitor benchmark", ""), IF(K11 > 3, "Strong ads", ""), IF(J11 > 0.4, "High ad cost", "") ) -> Overstock, Competitor benchmark, Strong ads, High ad cost | U11: =IF(Table3[[#This Row],[Final_Recommended_Price]]>Table3[[#This Row],[Min_Price]],"Yes","No") -> No | V11: =IF( S11=C11, "Minimum margin constraint", IF( G11<>"", "Competitor benchmark", IF( O11>1, "Low inventory", IF( O11<1, "Overstock", IF( Q11>1, "Strong demand / ads", IF(Q11<1, "High ad cost", "Neutral") ) ) ) ) ) -> Minimum margin constraint
A12: MN-11 | B12: =IFERROR(INDEX(Pricing_Data[Total_Cost],MATCH(Pricing_model!A12,Pricing_Data[SKU],0)),"") -> 15.26 | C12: =INDEX(Pricing_Data[Min_Price],MATCH(A12,Pricing_Data[SKU],0)) -> 19.075 | D12: =INDEX(Pricing_Data[Target_Price],MATCH(Pricing_model!A12,Pricing_Data[SKU],0)) -> 23.476923 | E12: =INDEX(Competitor_Data[Lowest_Competitor_Price],MATCH(Pricing_model!A12,Competitor_Data[SKU],0)) -> 14.99 | F12: =INDEX(Competitor_Data[Highest_Competitor_Price],MATCH(Pricing_model!A12,Competitor_Data[SKU],0)) -> 23.5 | G12: =INDEX(Competitor_Data[Avg_Competitor_Price],MATCH(Pricing_model!A12,Competitor_Data[SKU],0)) -> 17.8 | H12: =INDEX(Inventory_Health__2[days-of-supply],MATCH(Pricing_model!A12,Inventory_Health__2[SKU],0)) -> 159 | I12: =INDEX(Inventory_Health__2[weeks-of-cover-t30],MATCH(Pricing_model!A12,Inventory_Health__2[SKU],0)) -> 8 | J12: =INDEX(Ads_Performance!AF22:AF71,MATCH(Pricing_model!A12,Ads_Performance!AE22:AE71,0)) -> 19.915199 | K12: =INDEX(Ads_Performance!AG22:AG71,MATCH(Pricing_model!A12,Ads_Performance!AE22:AE71,0)) -> 5.6579079 | L12: =INDEX(Historical_Sales!O18:O67,MATCH(Pricing_model!A12,Historical_Sales!L18:L67,0)) -> 0.13393871 | M12: =D12 -> 23.476923 | N12: =IF(AND(G12<>"", M12> G12),G12,M12) -> 17.8 | O12: =IF( H12=0, 1, IF( H12 < 45, 1.05, IF( H12 > 90, 0.95, IF( I12 > 10, 0.95, 1 ) ) ) ) -> 0.95 | P12: =N12*O12 -> 16.91 | Q12: =IF( AND(K12>=6, L12>=0.3, J12<=35), 1.03, IF(OR(J12>35, K12<3), 0.95, 1) ) -> 1 | R12: =P12*Q12 -> 16.91 | S12: =MAX(R12,C12) -> 19.075 | T12: =_xlfn.TEXTJOIN(", ", TRUE, IF(H12 < 15, "Low inventory", ""), IF(I12 > 8, "Overstock", ""), IF(G12<>"", "Competitor benchmark", ""), IF(K12 > 3, "Strong ads", ""), IF(J12 > 0.4, "High ad cost", "") ) -> Competitor benchmark, Strong ads, High ad cost | U12: =IF(Table3[[#This Row],[Final_Recommended_Price]]>Table3[[#This Row],[Min_Price]],"Yes","No") -> No | V12: =IF( S12=C12, "Minimum margin constraint", IF( G12<>"", "Competitor benchmark", IF( O12>1, "Low inventory", IF( O12<1, "Overstock", IF( Q12>1, "Strong demand / ads", IF(Q12<1, "High ad cost", "Neutral") ) ) ) ) ) -> Minimum margin constraint
A13: MN-12 | B13: =IFERROR(INDEX(Pricing_Data[Total_Cost],MATCH(Pricing_model!A13,Pricing_Data[SKU],0)),"") -> 17.87 | C13: =INDEX(Pricing_Data[Min_Price],MATCH(A13,Pricing_Data[SKU],0)) -> 22.3375 | D13: =INDEX(Pricing_Data[Target_Price],MATCH(Pricing_model!A13,Pricing_Data[SKU],0)) -> 27.492308 | E13: =INDEX(Competitor_Data[Lowest_Competitor_Price],MATCH(Pricing_model!A13,Competitor_Data[SKU],0)) -> 17.95 | F13: =INDEX(Competitor_Data[Highest_Competitor_Price],MATCH(Pricing_model!A13,Competitor_Data[SKU],0)) -> 27.9 | G13: =INDEX(Competitor_Data[Avg_Competitor_Price],MATCH(Pricing_model!A13,Competitor_Data[SKU],0)) -> 21.4 | H13: =INDEX(Inventory_Health__2[days-of-supply],MATCH(Pricing_model!A13,Inventory_Health__2[SKU],0)) -> 74 | I13: =INDEX(Inventory_Health__2[weeks-of-cover-t30],MATCH(Pricing_model!A13,Inventory_Health__2[SKU],0)) -> 3 | J13: =INDEX(Ads_Performance!AF23:AF72,MATCH(Pricing_model!A13,Ads_Performance!AE23:AE72,0)) -> 37.854601 | K13: =INDEX(Ads_Performance!AG23:AG72,MATCH(Pricing_model!A13,Ads_Performance!AE23:AE72,0)) -> 3.7928957 | L13: =INDEX(Historical_Sales!O19:O68,MATCH(Pricing_model!A13,Historical_Sales!L19:L68,0)) -> 0.17254902 | M13: =D13 -> 27.492308 | N13: =IF(AND(G13<>"", M13> G13),G13,M13) -> 21.4 | O13: =IF( H13=0, 1, IF( H13 < 45, 1.05, IF( H13 > 90, 0.95, IF( I13 > 10, 0.95, 1 ) ) ) ) -> 1 | P13: =N13*O13 -> 21.4 | Q13: =IF( AND(K13>=6, L13>=0.3, J13<=35), 1.03, IF(OR(J13>35, K13<3), 0.95, 1) ) -> 0.95 | R13: =P13*Q13 -> 20.33 | S13: =MAX(R13,C13) -> 22.3375 | T13: =_xlfn.TEXTJOIN(", ", TRUE, IF(H13 < 15, "Low inventory", ""), IF(I13 > 8, "Overstock", ""), IF(G13<>"", "Competitor benchmark", ""), IF(K13 > 3, "Strong ads", ""), IF(J13 > 0.4, "High ad cost", "") ) -> Competitor benchmark, Strong ads, High ad cost | U13: =IF(Table3[[#This Row],[Final_Recommended_Price]]>Table3[[#This Row],[Min_Price]],"Yes","No") -> No | V13: =IF( S13=C13, "Minimum margin constraint", IF( G13<>"", "Competitor benchmark", IF( O13>1, "Low inventory", IF( O13<1, "Overstock", IF( Q13>1, "Strong demand / ads", IF(Q13<1, "High ad cost", "Neutral") ) ) ) ) ) -> Minimum margin constraint
... A51: MN-50 | B51: =IFERROR(INDEX(Pricing_Data[Total_Cost],MATCH(Pricing_model!A51,Pricing_Data[SKU],0)),"") -> 27.6 | C51: =INDEX(Pricing_Data[Min_Price],MATCH(A51,Pricing_Data[SKU],0)) -> 34.5 | D51: =INDEX(Pricing_Data[Target_Price],MATCH(Pricing_model!A51,Pricing_Data[SKU],0)) -> 42.461538 | E51: =INDEX(Competitor_Data[Lowest_Competitor_Price],MATCH(Pricing_model!A51,Competitor_Data[SKU],0)) -> 24.95 | F51: =INDEX(Competitor_Data[Highest_Competitor_Price],MATCH(Pricing_model!A51,Competitor_Data[SKU],0)) -> 38.9 | G51: =INDEX(Competitor_Data[Avg_Competitor_Price],MATCH(Pricing_model!A51,Competitor_Data[SKU],0)) -> 30.2 | H51: =INDEX(Inventory_Health__2[days-of-supply],MATCH(Pricing_model!A51,Inventory_Health__2[SKU],0)) -> 49 | I51: =INDEX(Inventory_Health__2[weeks-of-cover-t30],MATCH(Pricing_model!A51,Inventory_Health__2[SKU],0)) -> 3 | J51: =INDEX(Ads_Performance!AF61:AF110,MATCH(Pricing_model!A51,Ads_Performance!AE61:AE110,0)) -> 12.42124 | K51: =INDEX(Ads_Performance!AG61:AG110,MATCH(Pricing_model!A51,Ads_Performance!AE61:AE110,0)) -> 6.89907 | L51: =INDEX(Historical_Sales!O57:O106,MATCH(Pricing_model!A51,Historical_Sales!L57:L106,0)) -> 0.20022185 | M51: =D51 -> 42.461538 | N51: =IF(AND(G51<>"", M51> G51),G51,M51) -> 30.2 | O51: =IF( H51=0, 1, IF( H51 < 45, 1.05, IF( H51 > 90, 0.95, IF( I51 > 10, 0.95, 1 ) ) ) ) -> 1 | P51: =N51*O51 -> 30.2 | Q51: =IF( AND(K51>=6, L51>=0.3, J51<=35), 1.03, IF(OR(J51>35, K51<3), 0.95, 1) ) -> 1 | R51: =P51*Q51 -> 30.2 | S51: =MAX(R51,C51) -> 34.5 | T51: =_xlfn.TEXTJOIN(", ", TRUE, IF(H51 < 15, "Low inventory", ""), IF(I51 > 8, "Overstock", ""), IF(G51<>"", "Competitor benchmark", ""), IF(K51 > 3, "Strong ads", ""), IF(J51 > 0.4, "High ad cost", "") ) -> Competitor benchmark, Strong ads, High ad cost | U51: =IF(Table3[[#This Row],[Final_Recommended_Price]]>Table3[[#This Row],[Min_Price]],"Yes","No") -> No | V51: =IF( S51=C51, "Minimum margin constraint", IF( G51<>"", "Competitor benchmark", IF( O51>1, "Low inventory", IF( O51<1, "Overstock", IF( Q51>1, "Strong demand / ads", IF(Q51<1, "High ad cost", "Neutral") ) ) ) ) ) -> Minimum margin constraint

Sheet Pricing_Action_View
A1: SKU | B1: Current_Price | C1: Final_Recommended_Price | D1: Price_Change_on_CurrentPrice | E1: Min_Price | F1: Price_Increase_Potential | G1: Primary_Pricing_Driver | H1: Action_Recommended | I1: Return_Risk
A2: =Pricing_Data[[#This Row],[SKU]] -> MN-01 | B2: =Pricing_Data[[#This Row],[Current_Price]] -> 38.9 | C2: =Table3[[#This Row],[Final_Recommended_Price]] -> 40.375 | D2: =C2-B2 -> 1.475 | E2: =Pricing_Data[[#This Row],[Min_Price]] -> 40.375 | F2: =Table3[[#This Row],[Price_Increase_Potential]] -> No | G2: =Table3[[#This Row],[Primary_Pricing_Driver]] -> Minimum margin constraint | H2: =IF( G2="Minimum margin constraint", "Hold price (margin floor)", IF( C2 > B2, "Increase price", IF( C2 < B2, "Decrease price", "Hold price" ) ) ) -> Hold price (margin floor) | I2: =INDEX(Returns_Data[Return_Risk],MATCH(Table8[[#This Row],[SKU]],Returns_Data[SKU],0)) -> Low Risk
A3: =Pricing_Data[[#This Row],[SKU]] -> MN-02 | B3: =Pricing_Data[[#This Row],[Current_Price]] -> 33.9 | C3: =Table3[[#This Row],[Final_Recommended_Price]] -> 33.25 | D3: =C3-B3 -> -0.65 | E3: =Pricing_Data[[#This Row],[Min_Price]] -> 33.25 | F3: =Table3[[#This Row],[Price_Increase_Potential]] -> No | G3: =Table3[[#This Row],[Primary_Pricing_Driver]] -> Minimum margin constraint | H3: =IF( G3="Minimum margin constraint", "Hold price (margin floor)", IF( C3 > B3, "Increase price", IF( C3 < B3, "Decrease price", "Hold price" ) ) ) -> Hold price (margin floor) | I3: =INDEX(Returns_Data[Return_Risk],MATCH(Table8[[#This Row],[SKU]],Returns_Data[SKU],0)) -> Low Risk
A4: =Pricing_Data[[#This Row],[SKU]] -> MN-03 | B4: =Pricing_Data[[#This Row],[Current_Price]] -> 34.9 | C4: =Table3[[#This Row],[Final_Recommended_Price]] -> 37.5375 | D4: =C4-B4 -> 2.6375 | E4: =Pricing_Data[[#This Row],[Min_Price]] -> 37.5375 | F4: =Table3[[#This Row],[Price_Increase_Potential]] -> No | G4: =Table3[[#This Row],[Primary_Pricing_Driver]] -> Minimum margin constraint | H4: =IF( G4="Minimum margin constraint", "Hold price (margin floor)", IF( C4 > B4, "Increase price", IF( C4 < B4, "Decrease price", "Hold price" ) ) ) -> Hold price (margin floor) | I4: =INDEX(Returns_Data[Return_Risk],MATCH(Table8[[#This Row],[SKU]],Returns_Data[SKU],0)) -> Low Risk
A5: =Pricing_Data[[#This Row],[SKU]] -> MN-04 | B5: =Pricing_Data[[#This Row],[Current_Price]] -> 29.9 | C5: =Table3[[#This Row],[Final_Recommended_Price]] -> 32.425 | D5: =C5-B5 -> 2.525 | E5: =Pricing_Data[[#This Row],[Min_Price]] -> 32.425 | F5: =Table3[[#This Row],[Price_Increase_Potential]] -> No | G5: =Table3[[#This Row],[Primary_Pricing_Driver]] -> Minimum margin constraint | H5: =IF( G5="Minimum margin constraint", "Hold price (margin floor)", IF( C5 > B5, "Increase price", IF( C5 < B5, "Decrease price", "Hold price" ) ) ) -> Hold price (margin floor) | I5: =INDEX(Returns_Data[Return_Risk],MATCH(Table8[[#This Row],[SKU]],Returns_Data[SKU],0)) -> Low Risk
A6: =Pricing_Data[[#This Row],[SKU]] -> MN-05 | B6: =Pricing_Data[[#This Row],[Current_Price]] -> 21.9 | C6: =Table3[[#This Row],[Final_Recommended_Price]] -> 34.36 | D6: =C6-B6 -> 12.46 | E6: =Pricing_Data[[#This Row],[Min_Price]] -> 34.36 | F6: =Table3[[#This Row],[Price_Increase_Potential]] -> No | G6: =Table3[[#This Row],[Primary_Pricing_Driver]] -> Minimum margin constraint | H6: =IF( G6="Minimum margin constraint", "Hold price (margin floor)", IF( C6 > B6, "Increase price", IF( C6 < B6, "Decrease price", "Hold price" ) ) ) -> Hold price (margin floor) | I6: =INDEX(Returns_Data[Return_Risk],MATCH(Table8[[#This Row],[SKU]],Returns_Data[SKU],0)) -> Low Risk
A7: =Pricing_Data[[#This Row],[SKU]] -> MN-06 | B7: =Pricing_Data[[#This Row],[Current_Price]] -> 14.95 | C7: =Table3[[#This Row],[Final_Recommended_Price]] -> 19.16 | D7: =C7-B7 -> 4.21 | E7: =Pricing_Data[[#This Row],[Min_Price]] -> 19.16 | F7: =Table3[[#This Row],[Price_Increase_Potential]] -> No | G7: =Table3[[#This Row],[Primary_Pricing_Driver]] -> Minimum margin constraint | H7: =IF( G7="Minimum margin constraint", "Hold price (margin floor)", IF( C7 > B7, "Increase price", IF( C7 < B7, "Decrease price", "Hold price" ) ) ) -> Hold price (margin floor) | I7: =INDEX(Returns_Data[Return_Risk],MATCH(Table8[[#This Row],[SKU]],Returns_Data[SKU],0)) -> Low Risk
A8: =Pricing_Data[[#This Row],[SKU]] -> MN-07 | B8: =Pricing_Data[[#This Row],[Current_Price]] -> 17.89 | C8: =Table3[[#This Row],[Final_Recommended_Price]] -> 89.325 | D8: =C8-B8 -> 71.435 | E8: =Pricing_Data[[#This Row],[Min_Price]] -> 89.325 | F8: =Table3[[#This Row],[Price_Increase_Potential]] -> No | G8: =Table3[[#This Row],[Primary_Pricing_Driver]] -> Minimum margin constraint | H8: =IF( G8="Minimum margin constraint", "Hold price (margin floor)", IF( C8 > B8, "Increase price", IF( C8 < B8, "Decrease price", "Hold price" ) ) ) -> Hold price (margin floor) | I8: =INDEX(Returns_Data[Return_Risk],MATCH(Table8[[#This Row],[SKU]],Returns_Data[SKU],0)) -> Low Risk
A9: =Pricing_Data[[#This Row],[SKU]] -> MN-08 | B9: =Pricing_Data[[#This Row],[Current_Price]] -> 29.9 | C9: =Table3[[#This Row],[Final_Recommended_Price]] -> 34.813333 | D9: =C9-B9 -> 4.9133333 | E9: =Pricing_Data[[#This Row],[Min_Price]] -> 34.813333 | F9: =Table3[[#This Row],[Price_Increase_Potential]] -> No | G9: =Table3[[#This Row],[Primary_Pricing_Driver]] -> Minimum margin constraint | H9: =IF( G9="Minimum margin constraint", "Hold price (margin floor)", IF( C9 > B9, "Increase price", IF( C9 < B9, "Decrease price", "Hold price" ) ) ) -> Hold price (margin floor) | I9: =INDEX(Returns_Data[Return_Risk],MATCH(Table8[[#This Row],[SKU]],Returns_Data[SKU],0)) -> Low Risk
A10: =Pricing_Data[[#This Row],[SKU]] -> MN-09 | B10: =Pricing_Data[[#This Row],[Current_Price]] -> 14.9 | C10: =Table3[[#This Row],[Final_Recommended_Price]] -> 19.893333 | D10: =C10-B10 -> 4.9933333 | E10: =Pricing_Data[[#This Row],[Min_Price]] -> 19.893333 | F10: =Table3[[#This Row],[Price_Increase_Potential]] -> No | G10: =Table3[[#This Row],[Primary_Pricing_Driver]] -> Minimum margin constraint | H10: =IF( G10="Minimum margin constraint", "Hold price (margin floor)", IF( C10 > B10, "Increase price", IF( C10 < B10, "Decrease price", "Hold price" ) ) ) -> Hold price (margin floor) | I10: =INDEX(Returns_Data[Return_Risk],MATCH(Table8[[#This Row],[SKU]],Returns_Data[SKU],0)) -> Low Risk
A11: =Pricing_Data[[#This Row],[SKU]] -> MN-10 | B11: =Pricing_Data[[#This Row],[Current_Price]] -> 19.9 | C11: =Table3[[#This Row],[Final_Recommended_Price]] -> 21.75 | D11: =C11-B11 -> 1.85 | E11: =Pricing_Data[[#This Row],[Min_Price]] -> 21.75 | F11: =Table3[[#This Row],[Price_Increase_Potential]] -> No | G11: =Table3[[#This Row],[Primary_Pricing_Driver]] -> Minimum margin constraint | H11: =IF( G11="Minimum margin constraint", "Hold price (margin floor)", IF( C11 > B11, "Increase price", IF( C11 < B11, "Decrease price", "Hold price" ) ) ) -> Hold price (margin floor) | I11: =INDEX(Returns_Data[Return_Risk],MATCH(Table8[[#This Row],[SKU]],Returns_Data[SKU],0)) -> Low Risk
A12: =Pricing_Data[[#This Row],[SKU]] -> MN-11 | B12: =Pricing_Data[[#This Row],[Current_Price]] -> 16.9 | C12: =Table3[[#This Row],[Final_Recommended_Price]] -> 19.075 | D12: =C12-B12 -> 2.175 | E12: =Pricing_Data[[#This Row],[Min_Price]] -> 19.075 | F12: =Table3[[#This Row],[Price_Increase_Potential]] -> No | G12: =Table3[[#This Row],[Primary_Pricing_Driver]] -> Minimum margin constraint | H12: =IF( G12="Minimum margin constraint", "Hold price (margin floor)", IF( C12 > B12, "Increase price", IF( C12 < B12, "Decrease price", "Hold price" ) ) ) -> Hold price (margin floor) | I12: =INDEX(Returns_Data[Return_Risk],MATCH(Table8[[#This Row],[SKU]],Returns_Data[SKU],0)) -> Low Risk
A13: =Pricing_Data[[#This Row],[SKU]] -> MN-12 | B13: =Pricing_Data[[#This Row],[Current_Price]] -> 19.9 | C13: =Table3[[#This Row],[Final_Recommended_Price]] -> 22.3375 | D13: =C13-B13 -> 2.4375 | E13: =Pricing_Data[[#This Row],[Min_Price]] -> 22.3375 | F13: =Table3[[#This Row],[Price_Increase_Potential]] -> No | G13: =Table3[[#This Row],[Primary_Pricing_Driver]] -> Minimum margin constraint | H13: =IF( G13="Minimum margin constraint", "Hold price (margin floor)", IF( C13 > B13, "Increase price", IF( C13 < B13, "Decrease price", "Hold price" ) ) ) -> Hold price (margin floor) | I13: =INDEX(Returns_Data[Return_Risk],MATCH(Table8[[#This Row],[SKU]],Returns_Data[SKU],0)) -> Low Risk
... A51: =Pricing_Data[[#This Row],[SKU]] -> MN-50 | B51: =Pricing_Data[[#This Row],[Current_Price]] -> 29.9 | C51: =Table3[[#This Row],[Final_Recommended_Price]] -> 34.5 | D51: =C51-B51 -> 4.6 | E51: =Pricing_Data[[#This Row],[Min_Price]] -> 34.5 | F51: =Table3[[#This Row],[Price_Increase_Potential]] -> No | G51: =Table3[[#This Row],[Primary_Pricing_Driver]] -> Minimum margin constraint | H51: =IF( G51="Minimum margin constraint", "Hold price (margin floor)", IF( C51 > B51, "Increase price", IF( C51 < B51, "Decrease price", "Hold price" ) ) ) -> Hold price (margin floor) | I51: =INDEX(Returns_Data[Return_Risk],MATCH(Table8[[#This Row],[SKU]],Returns_Data[SKU],0)) -> Low Risk

Sheet Dashboard
A2: Pricing Insights & Recommendations Overview
A5: =COUNTA(Table3[SKU]) -> 50 | D5: =COUNTIF(Table3[Price_Increase_Potential],"Yes") -> 13 | G5: =COUNTIF(Table3[Primary_Pricing_Driver],"*constraint*") / COUNTA(Table3[SKU]) -> 0.74 | J5: =AVERAGE(Pricing_Action_View!D2:D51) -> 4.575151
A7: Total SKU | D7: SKUs with Pricing Headroom | G7: % Margin-Constrained SKUs | J7: Avg Price Change vs Current Price
A39: SKU | B39: Current Price | C39: Recommended Price | D39: Price Change | E39: Primary Driver | F39: Action | G39: Return Risk
A40: MN-13 | B40: $22.90 | C40: 24.2 | D40: $1.30 | E40: Competitor benchmark | F40: Increase price | G40: Low Risk | H40: The majority of SKUs are still limited by margin floors.
A41: MN-24 | B41: $19.90 | C41: 19.76 | D41: -$0.14 | E41: Competitor benchmark | F41: Decrease price | G41: Low Risk
A42: MN-29 | B42: $21.90 | C42: 22.8 | D42: $0.90 | E42: Competitor benchmark | F42: Increase price | G42: High Risk | H42: The upside in pricing is selective rather than widespread.
A43: MN-33 | B43: $25.90 | C43: 33.359323 | D43: $7.46 | E43: Overstock | F43: Increase price | G43: Low Risk
A44: MN-40 | B44: $23.90 | C44: 25.647 | D44: $1.75 | E44: Competitor benchmark | F44: Increase price | G44: Medium Risk | H44: The primary cause of increases is demand signals (ROAS + conversion).
A45: MN-41 | B45: $78.90 | C45: 84.975 | D45: $6.08 | E45: Competitor benchmark | F45: Increase price | G45: Medium Risk
A46: MN-42 | B46: $73.90 | C46: 79.104 | D46: $5.20 | E46: Competitor benchmark | F46: Increase price | G46: Medium Risk | H46: Strong demand signals and advantageous inventory positions are the main driver
A47: MN-43 | B47: $13.90 | C47: 14.06 | D47: $0.16 | E47: Competitor benchmark | F47: Increase price | G47: Low Risk | H47: of the pricing headroom seen in 13 SKUs.
A48: MN-44 | B48: $11.90 | C48: 14.118462 | D48: $2.22 | E48: Overstock | F48: Increase price | G48: Low Risk
A49: MN-45 | B49: $29.90 | C49: 32.342 | D49: $2.44 | E49: Competitor benchmark | F49: Increase price | G49: Low Risk
A50: MN-46 | B50: $26.90 | C50: 27.455 | D50: $0.56 | E50: Competitor benchmark | F50: Increase price | G50: Low Risk
A51: MN-47 | B51: $76.90 | C51: 78.6714 | D51: $1.77 | E51: Competitor benchmark | F51: Increase price | G51: Low Risk
A52: MN-48 | B52: $89.90 | C52: 86.3037 | D52: -$3.60 | E52: Competitor benchmark | F52: Decrease price | G52: Low Risk

Sheet Pricing_Data
A1: SKU | B1: Product_description | C1: Product Role | D1: Country_of_Origin | E1: FBA Fee | F1: Storage Fee | G1: Handling_Cost | H1: Cost | I1: Current_Price | J1: Minimum_Acceptable_Margin_% | K1: Target_Gross_Margin_% | L1: Total_Cost | M1: Min_Price | N1: Target_Price
A2: MN-01 | B2: Rectangle Tray -14 x 10 Inch - Pk of 25 | C2: Core | D2: India | E2: 15.11 | F2: 0.44 | G2: 0.75 | H2: 16 | I2: 38.9 | J2: 0.2 | K2: 0.35 | L2: =Pricing_Data[[#This Row],[FBA Fee]]+Pricing_Data[[#This Row],[Storage Fee]]+Pricing_Data[[#This Row],[Handling_Cost]]+Pricing_Data[[#This Row],[Cost]] -> 32.3 | M2: =Pricing_Data[[#This Row],[Total_Cost]] / (1-Pricing_Data[[#This Row],[Minimum_Acceptable_Margin_%]]) -> 40.375 | N2: =Pricing_Data[[#This Row],[Total_Cost]] / (1-Pricing_Data[[#This Row],[Target_Gross_Margin_%]]) -> 49.692308
A3: MN-02 | B3: Rectangle Tray -12x10 - Pk of 25 | C3: Core | D3: India | E3: 13.55 | F3: 0.3 | G3: 0.75 | H3: 12 | I3: 33.9 | J3: 0.2 | K3: 0.35 | L3: =Pricing_Data[[#This Row],[FBA Fee]]+Pricing_Data[[#This Row],[Storage Fee]]+Pricing_Data[[#This Row],[Handling_Cost]]+Pricing_Data[[#This Row],[Cost]] -> 26.6 | M3: =Pricing_Data[[#This Row],[Total_Cost]] / (1-Pricing_Data[[#This Row],[Minimum_Acceptable_Margin_%]]) -> 33.25 | N3: =Pricing_Data[[#This Row],[Total_Cost]] / (1-Pricing_Data[[#This Row],[Target_Gross_Margin_%]]) -> 40.923077
A4: MN-03 | B4: Oval Tray -15x10 Inch - Pk of 25 | C4: Core | D4: India | E4: 13.94 | F4: 0.34 | G4: 0.75 | H4: 15 | I4: 34.9 | J4: 0.2 | K4: 0.35 | L4: =Pricing_Data[[#This Row],[FBA Fee]]+Pricing_Data[[#This Row],[Storage Fee]]+Pricing_Data[[#This Row],[Handling_Cost]]+Pricing_Data[[#This Row],[Cost]] -> 30.03 | M4: =Pricing_Data[[#This Row],[Total_Cost]] / (1-Pricing_Data[[#This Row],[Minimum_Acceptable_Margin_%]]) -> 37.5375 | N4: =Pricing_Data[[#This Row],[Total_Cost]] / (1-Pricing_Data[[#This Row],[Target_Gross_Margin_%]]) -> 46.2
A5: MN-04 | B5: Oval Tray - 13x9 Inch - pk of 25 | C5: Core | D5: India | E5: 12.89 | F5: 0.3 | G5: 0.75 | H5: 12 | I5: 29.9 | J5: 0.2 | K5: 0.35 | L5: =Pricing_Data[[#This Row],[FBA Fee]]+Pricing_Data[[#This Row],[Storage Fee]]+Pricing_Data[[#This Row],[Handling_Cost]]+Pricing_Data[[#This Row],[Cost]] -> 25.94 | M5: =Pricing_Data[[#This Row],[Total_Cost]] / (1-Pricing_Data[[#This Row],[Minimum_Acceptable_Margin_%]]) -> 32.425 | N5: =Pricing_Data[[#This Row],[Total_Cost]] / (1-Pricing_Data[[#This Row],[Target_Gross_Margin_%]]) -> 39.907692
A6: MN-05 | B6: Christmas Tray - 17x12 Inch - Pk of 5 | C6: Seasonal | D6: India | E6: 11.8 | F6: 0.22 | G6: 0.75 | H6: 13 | I6: 21.9 | J6: 0.25 | K6: 0.45 | L6: =Pricing_Data[[#This Row],[FBA Fee]]+Pricing_Data[[#This Row],[Storage Fee]]+Pricing_Data[[#This Row],[Handling_Cost]]+Pricing_Data[[#This Row],[Cost]] -> 25.77 | M6: =Pricing_Data[[#This Row],[Total_Cost]] / (1-Pricing_Data[[#This Row],[Minimum_Acceptable_Margin_%]]) -> 34.36 | N6: =Pricing_Data[[#This Row],[Total_Cost]] / (1-Pricing_Data[[#This Row],[Target_Gross_Margin_%]]) -> 46.854545
A7: MN-06 | B7: Star Tray - 14 Inch - Pk of 5 | C7: Seasonal | D7: India | E7: 8.5 | F7: 0.12 | G7: 0.75 | H7: 5 | I7: 14.95 | J7: 0.25 | K7: 0.45 | L7: =Pricing_Data[[#This Row],[FBA Fee]]+Pricing_Data[[#This Row],[Storage Fee]]+Pricing_Data[[#This Row],[Handling_Cost]]+Pricing_Data[[#This Row],[Cost]] -> 14.37 | M7: =Pricing_Data[[#This Row],[Total_Cost]] / (1-Pricing_Data[[#This Row],[Minimum_Acceptable_Margin_%]]) -> 19.16 | N7: =Pricing_Data[[#This Row],[Total_Cost]] / (1-Pricing_Data[[#This Row],[Target_Gross_Margin_%]]) -> 26.127273
A8: MN-07 | B8: 15 Round plate - pk of 10 | C8: Core | D8: India | E8: 17.85 | F8: 17.86 | G8: 17.87 | H8: 17.88 | I8: 17.89 | J8: 0.2 | K8: 0.35 | L8: =Pricing_Data[[#This Row],[FBA Fee]]+Pricing_Data[[#This Row],[Storage Fee]]+Pricing_Data[[#This Row],[Handling_Cost]]+Pricing_Data[[#This Row],[Cost]] -> 71.46 | M8: =Pricing_Data[[#This Row],[Total_Cost]] / (1-Pricing_Data[[#This Row],[Minimum_Acceptable_Margin_%]]) -> 89.325 | N8: =Pricing_Data[[#This Row],[Total_Cost]] / (1-Pricing_Data[[#This Row],[Target_Gross_Margin_%]]) -> 109.93846
A9: MN-08 | B9: 10 Inch Heart Plates - pk of 25 | C9: Seasonal | D9: India | E9: 12.11 | F9: 0.25 | G9: 0.75 | H9: 13 | I9: 29.9 | J9: 0.25 | K9: 0.45 | L9: =Pricing_Data[[#This Row],[FBA Fee]]+Pricing_Data[[#This Row],[Storage Fee]]+Pricing_Data[[#This Row],[Handling_Cost]]+Pricing_Data[[#This Row],[Cost]] -> 26.11 | M9: =Pricing_Data[[#This Row],[Total_Cost]] / (1-Pricing_Data[[#This Row],[Minimum_Acceptable_Margin_%]]) -> 34.813333 | N9: =Pricing_Data[[#This Row],[Total_Cost]] / (1-Pricing_Data[[#This Row],[Target_Gross_Margin_%]]) -> 47.472727
A10: MN-09 | B10: 6 Inch Heart Plates - pk of 25 | C10: Seasonal | D10: India | E10: 8.08 | F10: 0.09 | G10: 0.75 | H10: 6 | I10: 14.9 | J10: 0.25 | K10: 0.45 | L10: =Pricing_Data[[#This Row],[FBA Fee]]+Pricing_Data[[#This Row],[Storage Fee]]+Pricing_Data[[#This Row],[Handling_Cost]]+Pricing_Data[[#This Row],[Cost]] -> 14.92 | M10: =Pricing_Data[[#This Row],[Total_Cost]] / (1-Pricing_Data[[#This Row],[Minimum_Acceptable_Margin_%]]) -> 19.893333 | N10: =Pricing_Data[[#This Row],[Total_Cost]] / (1-Pricing_Data[[#This Row],[Target_Gross_Margin_%]]) -> 27.127273
A11: MN-10 | B11: 9x6 Rectangle - pk of 25 | C11: Core | D11: India | E11: 9.52 | F11: 0.13 | G11: 0.75 | H11: 7 | I11: 19.9 | J11: 0.2 | K11: 0.35 | L11: =Pricing_Data[[#This Row],[FBA Fee]]+Pricing_Data[[#This Row],[Storage Fee]]+Pricing_Data[[#This Row],[Handling_Cost]]+Pricing_Data[[#This Row],[Cost]] -> 17.4 | M11: =Pricing_Data[[#This Row],[Total_Cost]] / (1-Pricing_Data[[#This Row],[Minimum_Acceptable_Margin_%]]) -> 21.75 | N11: =Pricing_Data[[#This Row],[Total_Cost]] / (1-Pricing_Data[[#This Row],[Target_Gross_Margin_%]]) -> 26.769231
A12: MN-11 | B12: Oval Tray - 13x9 Inch - pk of 10 | C12: Core | D12: India | E12: 9.36 | F12: 0.15 | G12: 0.75 | H12: 5 | I12: 16.9 | J12: 0.2 | K12: 0.35 | L12: =Pricing_Data[[#This Row],[FBA Fee]]+Pricing_Data[[#This Row],[Storage Fee]]+Pricing_Data[[#This Row],[Handling_Cost]]+Pricing_Data[[#This Row],[Cost]] -> 15.26 | M12: =Pricing_Data[[#This Row],[Total_Cost]] / (1-Pricing_Data[[#This Row],[Minimum_Acceptable_Margin_%]]) -> 19.075 | N12: =Pricing_Data[[#This Row],[Total_Cost]] / (1-Pricing_Data[[#This Row],[Target_Gross_Margin_%]]) -> 23.476923
A13: MN-12 | B13: 13 inch Round DEEP plate - pk of 10 | C13: Core | D13: India | E13: 10.9 | F13: 0.22 | G13: 0.75 | H13: 6 | I13: 19.9 | J13: 0.2 | K13: 0.35 | L13: =Pricing_Data[[#This Row],[FBA Fee]]+Pricing_Data[[#This Row],[Storage Fee]]+Pricing_Data[[#This Row],[Handling_Cost]]+Pricing_Data[[#This Row],[Cost]] -> 17.87 | M13: =Pricing_Data[[#This Row],[Total_Cost]] / (1-Pricing_Data[[#This Row],[Minimum_Acceptable_Margin_%]]) -> 22.3375 | N13: =Pricing_Data[[#This Row],[Total_Cost]] / (1-Pricing_Data[[#This Row],[Target_Gross_Margin_%]]) -> 27.492308
... A51: MN-50 | B51: 9x6 Rectangle - pk of 50 | C51: Core | D51: India | E51: 12.58 | F51: 0.27 | G51: 0.75 | H51: 14 | I51: 29.9 | J51: 0.2 | K51: 0.35 | L51: =Pricing_Data[[#This Row],[FBA Fee]]+Pricing_Data[[#This Row],[Storage Fee]]+Pricing_Data[[#This Row],[Handling_Cost]]+Pricing_Data[[#This Row],[Cost]] -> 27.6 | M51: =Pricing_Data[[#This Row],[Total_Cost]] / (1-Pricing_Data[[#This Row],[Minimum_Acceptable_Margin_%]]) -> 34.5 | N51: =Pricing_Data[[#This Row],[Total_Cost]] / (1-Pricing_Data[[#This Row],[Target_Gross_Margin_%]]) -> 42.461538

Sheet Returns_Data
A1: SKU | B1: Return Quantity (Last 7 days) | C1: Return Quantity (Last 30 days) | D1: Return Quantity (Last 60 days) | E1: Return Quantity (Last 90 days) | F1: Return_Risk
A2: MN-01 | B2: 0 | C2: 9 | D2: 18 | E2: 26 | F2: =IF( E2>100, "High Risk", IF( E2>=50, "Medium Risk", "Low Risk" ) ) -> Low Risk
A3: MN-02 | B3: 0 | C3: 4 | D3: 14 | E3: 24 | F3: =IF( E3>100, "High Risk", IF( E3>=50, "Medium Risk", "Low Risk" ) ) -> Low Risk
A4: MN-03 | B4: 1 | C4: 4 | D4: 10 | E4: 13 | F4: =IF( E4>100, "High Risk", IF( E4>=50, "Medium Risk", "Low Risk" ) ) -> Low Risk
A5: MN-04 | B5: 1 | C5: 4 | D5: 6 | E5: 16 | F5: =IF( E5>100, "High Risk", IF( E5>=50, "Medium Risk", "Low Risk" ) ) -> Low Risk
A6: MN-09 | B6: 0 | C6: 2 | D6: 7 | E6: 11 | F6: =IF( E6>100, "High Risk", IF( E6>=50, "Medium Risk", "Low Risk" ) ) -> Low Risk
A7: MN-08 | B7: 0 | C7: 3 | D7: 4 | E7: 6 | F7: =IF( E7>100, "High Risk", IF( E7>=50, "Medium Risk", "Low Risk" ) ) -> Low Risk
A8: MN-10 | B8: 2 | C8: 9 | D8: 11 | E8: 19 | F8: =IF( E8>100, "High Risk", IF( E8>=50, "Medium Risk", "Low Risk" ) ) -> Low Risk
A9: MN-11 | B9: 3 | C9: 6 | D9: 8 | E9: 10 | F9: =IF( E9>100, "High Risk", IF( E9>=50, "Medium Risk", "Low Risk" ) ) -> Low Risk
A10: MN-12 | B10: 4 | C10: 13 | D10: 17 | E10: 24 | F10: =IF( E10>100, "High Risk", IF( E10>=50, "Medium Risk", "Low Risk" ) ) -> Low Risk
A11: MN-13 | B11: 2 | C11: 4 | D11: 11 | E11: 16 | F11: =IF( E11>100, "High Risk", IF( E11>=50, "Medium Risk", "Low Risk" ) ) -> Low Risk
A12: MN-14 | B12: 23 | C12: 79 | D12: 112 | E12: 145 | F12: =IF( E12>100, "High Risk", IF( E12>=50, "Medium Risk", "Low Risk" ) ) -> High Risk
A13: MN-15 | B13: 16 | C13: 44 | D13: 79 | E13: 111 | F13: =IF( E13>100, "High Risk", IF( E13>=50, "Medium Risk", "Low Risk" ) ) -> High Risk
... A51: MN-06 | B51: 1 | C51: 2 | D51: 3 | E51: 3 | F51: =IF( E51>100, "High Risk", IF( E51>=50, "Medium Risk", "Low Risk" ) ) -> Low Risk

Sheet Inventory_Health
A1: SKU | B1: condition | C1: total-inventory | D1: available | E1: inbound-shipped | F1: inbound-received | G1: reserved-quantity | H1: unfulfillable-quantity | I1: inv-age-0-to-30-days | J1: inv-age-31-to-60-days | K1: inv-age-61-to-90-days | L1: inv-age-181-to-330-days | M1: inv-age-331-to-365-days | N1: inv-age-365-plus-days | O1: currency | P1: units-shipped-t7 | Q1: units-shipped-t30 | R1: units-shipped-t60 | S1: units-shipped-t90 | T1: sell-through | U1: item-volume | V1: volume-unit-measurement | W1: storage-type | X1: storage-volume | Y1: marketplace | Z1: days-of-supply | AA1: weeks-of-cover-t30 | AB1: weeks-of-cover-t90 | AC1: Calculated_Total_Inventory
A2: MN-01 | B2: New | C2: 382 | D2: 264 | E2: 40 | F2: 9 | G2: 68 | H2: 1 | I2: 12 | J2: 261 | K2: 56 | L2: 0 | M2: 0 | N2: 0 | O2: USD | P2: 59 | Q2: 203 | R2: 386 | S2: 574 | T2: 1.33 | U2: 0.546781 | V2: cubic feet | W2: Standard | X2: 144.35018 | Y2: US | Z2: 47 | AA2: 6 | AB2: 7 | AC2: =IFERROR(Inventory_Health__2[[#This Row],[available]]+Inventory_Health__2[[#This Row],[inbound-shipped]]+Inventory_Health__2[[#This Row],[inbound-received]]+Inventory_Health__2[[#This Row],[reserved-quantity]]-Inventory_Health__2[[#This Row],[unfulfillable-quantity]],0) -> 380
A3: MN-02 | B3: New | C3: 306 | D3: 206 | E3: 80 | F3: 2 | G3: 18 | H3: 0 | I3: 127 | J3: 91 | K3: 17 | L3: 0 | M3: 0 | N3: 0 | O3: USD | P3: 29 | Q3: 155 | R3: 261 | S3: 417 | T3: 1.56 | U3: 0.373971 | V3: cubic feet | W3: Standard | X3: 77.038026 | Y3: US | Z3: 85 | AA3: 7 | AB3: 8 | AC3: =IFERROR(Inventory_Health__2[[#This Row],[available]]+Inventory_Health__2[[#This Row],[inbound-shipped]]+Inventory_Health__2[[#This Row],[inbound-received]]+Inventory_Health__2[[#This Row],[reserved-quantity]]-Inventory_Health__2[[#This Row],[unfulfillable-quantity]],0) -> 306
A4: MN-03 | B4: New | C4: 139 | D4: 95 | E4: 40 | F4: 0 | G4: 3 | H4: 1 | I4: 42 | J4: 8 | K4: 62 | L4: 0 | M4: 0 | N4: 0 | O4: USD | P4: 13 | Q4: 67 | R4: 116 | S4: 179 | T4: 1.16 | U4: 0.425846 | V4: cubic feet | W4: Standard | X4: 40.45537 | Y4: US | Z4: 83 | AA4: 8 | AB4: 9 | AC4: =IFERROR(Inventory_Health__2[[#This Row],[available]]+Inventory_Health__2[[#This Row],[inbound-shipped]]+Inventory_Health__2[[#This Row],[inbound-received]]+Inventory_Health__2[[#This Row],[reserved-quantity]]-Inventory_Health__2[[#This Row],[unfulfillable-quantity]],0) -> 137
A5: MN-04 | B5: New | C5: 171 | D5: 70 | E5: 80 | F5: 8 | G5: 13 | H5: 0 | I5: 3 | J5: 84 | K5: 0 | L5: 0 | M5: 0 | N5: 0 | O5: USD | P5: 18 | Q5: 71 | R5: 128 | S5: 187 | T5: 1.65 | U5: 0.375575 | V5: cubic feet | W5: Standard | X5: 26.29025 | Y5: US | Z5: 99 | AA5: 8 | AB5: 10 | AC5: =IFERROR(Inventory_Health__2[[#This Row],[available]]+Inventory_Health__2[[#This Row],[inbound-shipped]]+Inventory_Health__2[[#This Row],[inbound-received]]+Inventory_Health__2[[#This Row],[reserved-quantity]]-Inventory_Health__2[[#This Row],[unfulfillable-quantity]],0) -> 171
A6: MN-05 | B6: New | C6: 283 | D6: 0 | E6: 0 | F6: 49 | G6: 234 | H6: 0 | I6: 53 | J6: 141 | K6: 0 | L6: 0 | M6: 0 | N6: 0 | O6: USD | P6: 249 | Q6: 491 | R6: 543 | S6: 557 | T6: 1.47 | U6: 0.270417 | V6: cubic feet | W6: Standard | X6: 0 | Y6: US | Z6: 145 | AA6: 0 | AB6: 1 | AC6: =IFERROR(Inventory_Health__2[[#This Row],[available]]+Inventory_Health__2[[#This Row],[inbound-shipped]]+Inventory_Health__2[[#This Row],[inbound-received]]+Inventory_Health__2[[#This Row],[reserved-quantity]]-Inventory_Health__2[[#This Row],[unfulfillable-quantity]],0) -> 283
A7: MN-06 | B7: New | C7: 21 | D7: 1 | E7: 0 | F7: 0 | G7: 20 | H7: 0 | I7: 8 | J7: 40 | K7: 0 | L7: 0 | M7: 0 | N7: 0 | O7: USD | P7: 61 | Q7: 131 | R7: 150 | S7: 173 | T7: 1.23 | U7: 0.155234 | V7: cubic feet | W7: Standard | X7: 0.155234 | Y7: US | Z7: 0 | AA7: 0 | AB7: 0 | AC7: =IFERROR(Inventory_Health__2[[#This Row],[available]]+Inventory_Health__2[[#This Row],[inbound-shipped]]+Inventory_Health__2[[#This Row],[inbound-received]]+Inventory_Health__2[[#This Row],[reserved-quantity]]-Inventory_Health__2[[#This Row],[unfulfillable-quantity]],0) -> 21
A8: MN-07 | B8: New | C8: 144 | D8: 134 | E8: 0 | F8: 0 | G8: 7 | H8: 3 | I8: 51 | J8: 45 | K8: 55 | L8: 0 | M8: 0 | N8: 0 | O8: USD | P8: 15 | Q8: 95 | R8: 150 | S8: 220 | T8: 1.25 | U8: 0.336372 | V8: cubic feet | W8: Oversize | X8: 45.073848 | Y8: US | Z8: 59 | AA8: 5 | AB8: 7 | AC8: =IFERROR(Inventory_Health__2[[#This Row],[available]]+Inventory_Health__2[[#This Row],[inbound-shipped]]+Inventory_Health__2[[#This Row],[inbound-received]]+Inventory_Health__2[[#This Row],[reserved-quantity]]-Inventory_Health__2[[#This Row],[unfulfillable-quantity]],0) -> 138
A9: MN-08 | B9: New | C9: 255 | D9: 95 | E9: 152 | F9: 0 | G9: 8 | H9: 0 | I9: 4 | J9: 42 | K9: 41 | L9: 17 | M9: 0 | N9: 0 | O9: USD | P9: 2 | Q9: 10 | R9: 18 | S9: 36 | T9: 0.37 | U9: 0.315957 | V9: cubic feet | W9: Standard | X9: 30.015915 | Y9: US | Z9: 103 | AA9: 98 | AB9: 89 | AC9: =IFERROR(Inventory_Health__2[[#This Row],[available]]+Inventory_Health__2[[#This Row],[inbound-shipped]]+Inventory_Health__2[[#This Row],[inbound-received]]+Inventory_Health__2[[#This Row],[reserved-quantity]]-Inventory_Health__2[[#This Row],[unfulfillable-quantity]],0) -> 255
A10: MN-09 | B10: New | C10: 211 | D10: 207 | E10: 0 | F10: 0 | G10: 3 | H10: 1 | I10: 3 | J10: 1 | K10: 203 | L10: 0 | M10: 0 | N10: 0 | O10: USD | P10: 3 | Q10: 19 | R10: 38 | S10: 66 | T10: 0.36 | U10: 0.108386 | V10: cubic feet | W10: Standard | X10: 22.435902 | Y10: US | Z10: 57 | AA10: 43 | AB10: 40 | AC10: =IFERROR(Inventory_Health__2[[#This Row],[available]]+Inventory_Health__2[[#This Row],[inbound-shipped]]+Inventory_Health__2[[#This Row],[inbound-received]]+Inventory_Health__2[[#This Row],[reserved-quantity]]-Inventory_Health__2[[#This Row],[unfulfillable-quantity]],0) -> 209
A11: MN-10 | B11: New | C11: 363 | D11: 102 | E11: 200 | F11: 16 | G11: 45 | H11: 0 | I11: 96 | J11: 10 | K11: 43 | L11: 0 | M11: 0 | N11: 0 | O11: USD | P11: 25 | Q11: 122 | R11: 177 | S11: 231 | T11: 1.17 | U11: 0.160565 | V11: cubic feet | W11: Standard | X11: 16.37763 | Y11: US | Z11: 150 | AA11: 10 | AB11: 17 | AC11: =IFERROR(Inventory_Health__2[[#This Row],[available]]+Inventory_Health__2[[#This Row],[inbound-shipped]]+Inventory_Health__2[[#This Row],[inbound-received]]+Inventory_Health__2[[#This Row],[reserved-quantity]]-Inventory_Health__2[[#This Row],[unfulfillable-quantity]],0) -> 363
A12: MN-11 | B12: New | C12: 230 | D12: 124 | E12: 100 | F12: 0 | G12: 6 | H12: 0 | I12: 5 | J12: 133 | K12: 0 | L12: 0 | M12: 0 | N12: 0 | O12: USD | P12: 12 | Q12: 101 | R12: 141 | S12: 215 | T12: 1.43 | U12: 0.183563 | V12: cubic feet | W12: Standard | X12: 22.761812 | Y12: US | Z12: 159 | AA12: 8 | AB12: 13 | AC12: =IFERROR(Inventory_Health__2[[#This Row],[available]]+Inventory_Health__2[[#This Row],[inbound-shipped]]+Inventory_Health__2[[#This Row],[inbound-received]]+Inventory_Health__2[[#This Row],[reserved-quantity]]-Inventory_Health__2[[#This Row],[unfulfillable-quantity]],0) -> 230
A13: MN-12 | B13: New | C13: 259 | D13: 87 | E13: 100 | F13: 0 | G13: 69 | H13: 3 | I13: 93 | J13: 56 | K13: 0 | L13: 0 | M13: 0 | N13: 0 | O13: USD | P13: 48 | Q13: 194 | R13: 291 | S13: 354 | T13: 1.69 | U13: 0.279394 | V13: cubic feet | W13: Standard | X13: 24.307278 | Y13: US | Z13: 74 | AA13: 3 | AB13: 6 | AC13: =IFERROR(Inventory_Health__2[[#This Row],[available]]+Inventory_Health__2[[#This Row],[inbound-shipped]]+Inventory_Health__2[[#This Row],[inbound-received]]+Inventory_Health__2[[#This Row],[reserved-quantity]]-Inventory_Health__2[[#This Row],[unfulfillable-quantity]],0) -> 253
... A19: MN-18 | B19: New | C19: 458 | D19: 261 | E19: 160 | F19: 6 | G19: 26 | H19: 5 | I19: 108 | J19: 225 | K19: 0 | L19: 0 | M19: 0 | N19: 0 | O19: USD | P19: 21 | Q19: 273 | R19: 482 | S19: 761 | T19: 1.81 | U19: 0.457576 | V19: cubic feet | W19: Standard | X19: 119.42734 | Y19: US | Z19: 90 | AA19: 6 | AB19: 7 | AC19: =IFERROR(Inventory_Health__2[[#This Row],[available]]+Inventory_Health__2[[#This Row],[inbound-shipped]]+Inventory_Health__2[[#This Row],[inbound-received]]+Inventory_Health__2[[#This Row],[reserved-quantity]]-Inventory_Health__2[[#This Row],[unfulfillable-quantity]],0) -> 448
A20: MN-19 | B20: New | D20: 342 | E20: 0 | F20: 1 | G20: 115 | H20: 2 | I20: 70 | J20: 429 | K20: 0 | L20: 0 | M20: 0 | N20: 0 | O20: USD | P20: 122 | Q20: 565 | R20: 994 | S20: 1485 | T20: 1.83 | U20: 0.636574 | V20: cubic feet | W20: Oversize | X20: 217.70831 | Y20: US | Z20: 15 | AA20: 2 | AB20: 3 | AC20: =IFERROR(Inventory_Health__2[[#This Row],[available]]+Inventory_Health__2[[#This Row],[inbound-shipped]]+Inventory_Health__2[[#This Row],[inbound-received]]+Inventory_Health__2[[#This Row],[reserved-quantity]]-Inventory_Health__2[[#This Row],[unfulfillable-quantity]],0) -> 456
A21: MN-20 | B21: New | C21: 1039 | D21: 712 | E21: 256 | F21: 0 | G21: 68 | H21: 3 | I21: 159 | J21: 684 | K21: 0 | L21: 0 | M21: 0 | N21: 0 | O21: USD | P21: 124 | Q21: 526 | R21: 1000 | S21: 1494 | T21: 1.15 | U21: 0.039821 | V21: cubic feet | W21: Standard | X21: 28.352552 | Y21: US | Z21: 66 | AA21: 7 | AB21: 8 | AC21: =IFERROR(Inventory_Health__2[[#This Row],[available]]+Inventory_Health__2[[#This Row],[inbound-shipped]]+Inventory_Health__2[[#This Row],[inbound-received]]+Inventory_Health__2[[#This Row],[reserved-quantity]]-Inventory_Health__2[[#This Row],[unfulfillable-quantity]],0) -> 1033
A22: MN-21 | B22: New | C22: 18 | D22: 2 | E22: 0 | F22: 0 | G22: 15 | H22: 1 | I22: 23 | J22: 16 | K22: 0 | L22: 0 | M22: 0 | N22: 0 | O22: USD | P22: 41 | Q22: 235 | R22: 432 | S22: 553 | T22: 3.18 | U22: 0.234841 | V22: cubic feet | W22: Standard | X22: 0.469682 | Y22: US | Z22: 0 | AA22: 0 | AB22: 0 | AC22: =IFERROR(Inventory_Health__2[[#This Row],[available]]+Inventory_Health__2[[#This Row],[inbound-shipped]]+Inventory_Health__2[[#This Row],[inbound-received]]+Inventory_Health__2[[#This Row],[reserved-quantity]]-Inventory_Health__2[[#This Row],[unfulfillable-quantity]],0) -> 16
A23: MN-22 | B23: New | C23: 395 | D23: 252 | E23: 100 | F23: 4 | G23: 38 | H23: 1 | I23: 268 | J23: 63 | K23: 0 | L23: 0 | M23: 0 | N23: 0 | O23: USD | P23: 78 | Q23: 355 | R23: 553 | S23: 733 | T23: 1.85 | U23: 0.257323 | V23: cubic feet | W23: Standard | X23: 64.845396 | Y23: US | Z23: 51 | AA23: 4 | AB23: 6 | AC23: =IFERROR(Inventory_Health__2[[#This Row],[available]]+Inventory_Health__2[[#This Row],[inbound-shipped]]+Inventory_Health__2[[#This Row],[inbound-received]]+Inventory_Health__2[[#This Row],[reserved-quantity]]-Inventory_Health__2[[#This Row],[unfulfillable-quantity]],0) -> 393
A24: MN-23 | B24: New | C24: 547 | D24: 285 | E24: 240 | F24: 0 | G24: 20 | H24: 2 | I24: 227 | J24: 122 | K24: 0 | L24: 0 | M24: 0 | N24: 0 | O24: USD | P24: 86 | Q24: 326 | R24: 496 | S24: 691 | T24: 1.64 | U24: 0.017404 | V24: cubic feet | W24: Standard | X24: 4.96014 | Y24: US | Z24: 73 | AA24: 6 | AB24: 9 | AC24: =IFERROR(Inventory_Health__2[[#This Row],[available]]+Inventory_Health__2[[#This Row],[inbound-shipped]]+Inventory_Health__2[[#This Row],[inbound-received]]+Inventory_Health__2[[#This Row],[reserved-quantity]]-Inventory_Health__2[[#This Row],[unfulfillable-quantity]],0) -> 543
